Workbook

Sheet summary
A1: system | B1: model | C1: context_precision | D1: context_recall | E1: faithfullness | F1: answer_correctness | G1: response_time
A2: basic_rag | B2: llama | C2: =result!Q197 -> 0.61794872 | D2: =result!S197 -> 0.53923077 | E2: =result!U197 -> 0.97755789 | F2: =result!W197 -> 0.40769231 | G2: 7.4147157
A3: basic_rag | B3: gemma | C3: =result!Y197 -> 0.64358974 | D3: =result!AA197 -> 0.5642735 | E3: =result!AC197 -> 0.97395829 | F3: =result!AE197 -> 0.42102564 | G3: 5.8762542
A4: basic_rag | B4: deepseek | C4: 0.63333333 | D4: 0.53837607 | E4: 0.97295649 | F4: =result!AM197 -> 0.4425641 | G4: 19.010033
A5: advanced_rag | B5: llama | C5: =result!AO197 -> 0.28974359 | D5: =result!AQ197 -> 0.31017094 | E5: =result!AS197 -> 0.96854701 | F5: =result!AU197 -> 0.22820513 | G5: 22.899666
A6: advanced_rag | B6: gemma | C6: 0.31282051 | D6: 0.29051282 | E6: 0.96191697 | F6: =result!BC197 -> 0.23641026 | G6: 15.421405
A7: advanced_rag | B7: deepseek | C7: =result!BE197 -> 0.32820513 | D7: =result!BG197 -> 0.30333333 | E7: =result!BI197 -> 0.980407 | F7: 0.27948718 | G7: 82.615385

Sheet result
A1: index | B1: user_query | C1: ref_answer | D1: ref_context | E1: l1_response | F1: g1_response | G1: d1_response | H1: l1_retrieved_context | I1: g1_retrieved_context | J1: d1_retrieved_context | K1: l2_response | L1: g2_response | M1: d2_response | N1: l2_retrieved_context | O1: g2_retrieved_context | P1: d2_retrieved_context | Q1: l1_contextual_precision_score | R1: l1_contextual_precision_reason | S1: l1_contextual_recall_score | T1: l1_contextual_recall_reason | U1: l1_faithfulness_score | V1: l1_faithfulness_reason | W1: L1_answer_correctness_score | X1: l1_answer_correctness_reason | Y1: g1_contextual_precision_score | Z1: g1_contextual_precision_reason | AA1: g1_contextual_recall_score | AB1: g1_contextual_recall_reason | AC1: g1_faithfulness_score | AD1: g1_faithfulness_reason | AE1: answer_correctness_score | AF1: answer_correctness_reason | AG1: d1_contextual_precision_score | AH1: d1_contextual_precision_reason | AI1: d1_contextual_recall_score | AJ1: d1_contextual_recall_reason | AK1: d1_faithfulness_score | AL1: d1_faithfulness_reason | AM1: answer_correctness_score | AN1: answer_correctness_reason | AO1: l2_contextual_precision_score | AP1: l2_contextual_precision_reason | AQ1: l2_contextual_recall_score | AR1: l2_contextual_recall_reason | AS1: l2_faithfulness_score | AT1: l2_faithfulness_reason | AU1: l2_answer_correctness_score | AV1: l2_answer_correctness_reason | AW1: g2_contextual_precision_score | AX1: g2_contextual_precision_reason | AY1: g2_contextual_recall_score | AZ1: g2_contextual_recall_reason | BA1: g2_faithfulness_score | BB1: g2_faithfulness_reason | BC1: g2_answer_correctness_score | BD1: g2_answer_correctness_reason | BE1: d2_contextual_precision_score | BF1: d2_contextual_precision_reason | BG1: d2_contextual_recall_score | BH1: d2_contextual_recall_reason | BI1: d2_faithfulness_score | BJ1: d2_faithfulness_reason | BK1: d2_answer_correctness_score | BL1: d2_answer_correctness_reason | BM1: data_type
A2: 1 | B2: Which month is set aside each year in the UAE for nationwide reading and literacy activities, including those associated with the Abu Dhabi Reads campaign? | C2: March | D2: Building on the Abu Dhabi Reads campaign launched in 2013, the month of March is dedicated annually to raising awareness of literacy in the community and in schools | E2: To answer this question, I will walk you through my thought process step by step. Step 1: Read the context carefully to understand the information provided. Step 2: Identify relevant sentences that may provide the answer. Step 3: Analyze each sentence for relevance and look for specific details. Upon reviewing the context, I found the following sentence: "Building on the Abu Dhabi Reads campaign launched in 2013, the month of March is dedicated annually to raising awareness of literacy in the community and in schools." Based on this sentence, it appears that the month set aside each year for nationwide reading and literacy activities, including those associated with the Abu Dhabi Reads campaign, is: March Therefore, my answer is: March | F2: Okay, let's break this down step by step to answer the question. 1. **Understand the Question:** The question asks about the specific month dedicated to reading and literacy activities in the UAE, particularly referencing the "Abu Dhabi Reads" campaign. 2. **Scan the Context:** I need to find the information within the provided text that answers this question. I'll quickly read through the entire text to locate relevant details. 3. **Identify the Relevant Information:** The text states: "Building on the Abu Dhabi Reads campaign launched in 2013, the month of March is dedicated annually to raising awareness of literacy in the community and in schools." 4. **Formulate the Answer:** Based on the information found, the answer is March. **Answer:** March | G2: March is set aside each year in the UAE for nationwide reading and literacy activities, including those associated with the Abu Dhabi Reads campaign. | H2: ['international reading performance benchmark for the Emirate. In 2016, the Emirate participated \nagain with nationally representative samples from schools that also included participation in the \nePIRLS assessment. The UAE Government recognizes the results of high -quality international \nassessments in the provision of insights and contribution toward improving education quality. \nAbu Dhabi has been undergoing significant education and systemic reform to standardize its \neducation models to meet the objectives of the National Agenda. Considering the substantial and \nongoing transformations, measuring significant impact could be considered premature. However, \nGovernment at the fed eral and n ational level s leveraged the results to strategize and promote \nreading initiatives for all schools and communities. Building on the Abu Dhabi Reads campaign \nlaunched in 2013, the month of March is dedicated annually to raising awareness of literacy in the \ncommunity and in schools.\n3', 'international reading performance benchmark for the Emirate. In 2016, the Emirate participated \nagain with nationally representative samples from schools that also included participation in the \nePIRLS assessment. The UAE Government recognizes the results of high -quality international \nassessments in the provision of insights and contribution toward improving education quality. \nAbu Dhabi has been undergoing significant education and systemic reform to standardize its \neducation models to meet the objectives of the National Agenda. Considering the substantial and \nongoing transformations, measuring significant impact could be considered premature. However, \nGovernment at the fed eral and n ational level s leveraged the results to strategize and promote \nreading initiatives for all schools and communities. Building on the Abu Dhabi Reads campaign \nlaunched in 2013, the month of March is dedicated annually to raising awareness of literacy in the \ncommunity and in schools.\n3', 'international reading performance benchmark for the Emirate. In 2016, the Emirate participated \nagain with nationally representative samples from schools that also included participation in the \nePIRLS assessment. The UAE Government recognizes the results of high -quality international \nassessments in the provision of insights and contribution toward improving education quality. \nAbu Dhabi has been undergoing significant education and systemic reform to standardize its \neducation models to meet the objectives of the National Agenda. Considering the substantial and \nongoing transformations, measuring significant impact could be considered premature. However, \nGovernment at the fed eral and n ational level s leveraged the results to strategize and promote \nreading initiatives for all schools and communities. Building on the Abu Dhabi Reads campaign \nlaunched in 2013, the month of March is dedicated annually to raising awareness of literacy in the \ncommunity and in schools.\n3', 'international reading performance benchmark for the Emirate. In 2016, the Emirate participated \nagain with nationally representative samples from schools that also included participation in the \nePIRLS assessment. The UAE Government recognizes the results of high -quality international \nassessments in the provision of insights and contribution toward improving education quality. \nAbu Dhabi has been undergoing significant education and systemic reform to standardize its \neducation models to meet the objectives of the National Agenda. Considering the substantial and \nongoing transformations, measuring significant impact could be considered premature. However, \nGovernment at the fed eral and n ational level s leveraged the results to strategize and promote \nreading initiatives for all schools and communities. Building on the Abu Dhabi Reads campaign \nlaunched in 2013, the month of March is dedicated annually to raising awareness of literacy in the \ncommunity and in schools.\n3'] | I2: ['international reading performance benchmark for the Emirate. In 2016, the Emirate participated \nagain with nationally representative samples from schools that also included participation in the \nePIRLS assessment. The UAE Government recognizes the results of high -quality international \nassessments in the provision of insights and contribution toward improving education quality. \nAbu Dhabi has been undergoing significant education and systemic reform to standardize its \neducation models to meet the objectives of the National Agenda. Considering the substantial and \nongoing transformations, measuring significant impact could be considered premature. However, \nGovernment at the fed eral and n ational level s leveraged the results to strategize and promote \nreading initiatives for all schools and communities. Building on the Abu Dhabi Reads campaign \nlaunched in 2013, the month of March is dedicated annually to raising awareness of literacy in the \ncommunity and in schools.\n3', 'international reading performance benchmark for the Emirate. In 2016, the Emirate participated \nagain with nationally representative samples from schools that also included participation in the \nePIRLS assessment. The UAE Government recognizes the results of high -quality international \nassessments in the provision of insights and contribution toward improving education quality. \nAbu Dhabi has been undergoing significant education and systemic reform to standardize its \neducation models to meet the objectives of the National Agenda. Considering the substantial and \nongoing transformations, measuring significant impact could be considered premature. However, \nGovernment at the fed eral and n ational level s leveraged the results to strategize and promote \nreading initiatives for all schools and communities. Building on the Abu Dhabi Reads campaign \nlaunched in 2013, the month of March is dedicated annually to raising awareness of literacy in the \ncommunity and in schools.\n3', 'international reading performance benchmark for the Emirate. In 2016, the Emirate participated \nagain with nationally representative samples from schools that also included participation in the \nePIRLS assessment. The UAE Government recognizes the results of high -quality international \nassessments in the provision of insights and contribution toward improving education quality. \nAbu Dhabi has been undergoing significant education and systemic reform to standardize its \neducation models to meet the objectives of the National Agenda. Considering the substantial and \nongoing transformations, measuring significant impact could be considered premature. However, \nGovernment at the fed eral and n ational level s leveraged the results to strategize and promote \nreading initiatives for all schools and communities. Building on the Abu Dhabi Reads campaign \nlaunched in 2013, the month of March is dedicated annually to raising awareness of literacy in the \ncommunity and in schools.\n3', 'international reading performance benchmark for the Emirate. In 2016, the Emirate participated \nagain with nationally representative samples from schools that also included participation in the \nePIRLS assessment. The UAE Government recognizes the results of high -quality international \nassessments in the provision of insights and contribution toward improving education quality. \nAbu Dhabi has been undergoing significant education and systemic reform to standardize its \neducation models to meet the objectives of the National Agenda. Considering the substantial and \nongoing transformations, measuring significant impact could be considered premature. However, \nGovernment at the fed eral and n ational level s leveraged the results to strategize and promote \nreading initiatives for all schools and communities. Building on the Abu Dhabi Reads campaign \nlaunched in 2013, the month of March is dedicated annually to raising awareness of literacy in the \ncommunity and in schools.\n3'] | J2: ['international reading performance benchmark for the Emirate. In 2016, the Emirate participated \nagain with nationally representative samples from schools that also included participation in the \nePIRLS assessment. The UAE Government recognizes the results of high -quality international \nassessments in the provision of insights and contribution toward improving education quality. \nAbu Dhabi has been undergoing significant education and systemic reform to standardize its \neducation models to meet the objectives of the National Agenda. Considering the substantial and \nongoing transformations, measuring significant impact could be considered premature. However, \nGovernment at the fed eral and n ational level s leveraged the results to strategize and promote \nreading initiatives for all schools and communities. Building on the Abu Dhabi Reads campaign \nlaunched in 2013, the month of March is dedicated annually to raising awareness of literacy in the \ncommunity and in schools.\n3', 'international reading performance benchmark for the Emirate. In 2016, the Emirate participated \nagain with nationally representative samples from schools that also included participation in the \nePIRLS assessment. The UAE Government recognizes the results of high -quality international \nassessments in the provision of insights and contribution toward improving education quality. \nAbu Dhabi has been undergoing significant education and systemic reform to standardize its \neducation models to meet the objectives of the National Agenda. Considering the substantial and \nongoing transformations, measuring significant impact could be considered premature. However, \nGovernment at the fed eral and n ational level s leveraged the results to strategize and promote \nreading initiatives for all schools and communities. Building on the Abu Dhabi Reads campaign \nlaunched in 2013, the month of March is dedicated annually to raising awareness of literacy in the \ncommunity and in schools.\n3', 'international reading performance benchmark for the Emirate. In 2016, the Emirate participated \nagain with nationally representative samples from schools that also included participation in the \nePIRLS assessment. The UAE Government recognizes the results of high -quality international \nassessments in the provision of insights and contribution toward improving education quality. \nAbu Dhabi has been undergoing significant education and systemic reform to standardize its \neducation models to meet the objectives of the National Agenda. Considering the substantial and \nongoing transformations, measuring significant impact could be considered premature. However, \nGovernment at the fed eral and n ational level s leveraged the results to strategize and promote \nreading initiatives for all schools and communities. Building on the Abu Dhabi Reads campaign \nlaunched in 2013, the month of March is dedicated annually to raising awareness of literacy in the \ncommunity and in schools.\n3', 'international reading performance benchmark for the Emirate. In 2016, the Emirate participated \nagain with nationally representative samples from schools that also included participation in the \nePIRLS assessment. The UAE Government recognizes the results of high -quality international \nassessments in the provision of insights and contribution toward improving education quality. \nAbu Dhabi has been undergoing significant education and systemic reform to standardize its \neducation models to meet the objectives of the National Agenda. Considering the substantial and \nongoing transformations, measuring significant impact could be considered premature. However, \nGovernment at the fed eral and n ational level s leveraged the results to strategize and promote \nreading initiatives for all schools and communities. Building on the Abu Dhabi Reads campaign \nlaunched in 2013, the month of March is dedicated annually to raising awareness of literacy in the \ncommunity and in schools.\n3'] | K2: Based on the information provided, the final answer to the main question is: The month set aside each year in the UAE for nationwide reading and literacy activities, including those associated with the Abu Dhabi Reads campaign, is March. | L2: The UAE designates March annually as the month for nationwide reading and literacy activities. This initiative is heavily supported by the Abu Dhabi Reads campaign, which launched in 2013 and focuses on raising awareness of literacy within the community and schools. The campaign’s annual focus on March underscores the UAE’s commitment to promoting reading and improving literacy rates across the nation. | M2: Based on the provided information, the UAE designates **March** annually for nationwide reading and literacy activities, and the Abu Dhabi Reads campaign is part of these initiatives. Therefore, the month set aside is **March**. | N2: international reading performance benchmark for the Emirate. In 2016, the Emirate participated again with nationally representative samples from schools that also included participation in the ePIRLS assessment. The UAE Government recognizes the results of high -quality international assessments in the provision of insights and contribution toward improving education quality. Abu Dhabi has been undergoing significant education and systemic reform to standardize its education models to meet the objectives of the National Agenda. Considering the substantial and ongoing transformations, measuring significant impact could be considered premature. However, Government at the fed eral and n ational level s leveraged the results to strategize and promote reading initiatives for all schools and communities. Building on the Abu Dhabi Reads campaign launched in 2013, the month of March is dedicated annually to raising awareness of literacy in the community and in schools. 3 international reading performance benchmark for the Emirate. In 2016, the Emirate participated again with nationally representative samples from schools that also included participation in the ePIRLS assessment. The UAE Government recognizes the results of high -quality international assessments in the provision of insights and contribution toward improving education quality. Abu Dhabi has been undergoing significant education and systemic reform to standardize its education models to meet the objectives of the National Agenda. Considering the substantial and ongoing transformations, measuring significant impact could be considered premature. However, Government at the fed eral and n ational level s leveraged the results to strategize and promote reading initiatives for all schools and communities. Building on the Abu Dhabi Reads campaign launched in 2013, the month of March is dedicated annually to raising awareness of literacy in the community and in schools. 3 international reading performance benchmark for the Emirate. In 2016, the Emirate participated again with nationally representative samples from schools that also included participation in the ePIRLS assessment. The UAE Government recognizes the results of high -quality international assessments in the provision of insights and contribution toward improving education quality. Abu Dhabi has been undergoing significant education and systemic reform to standardize its education models to meet the objectives of the National Agenda. Considering the substantial and ongoing transformations, measuring significant impact could be considered premature. However, Government at the fed eral and n ational level s leveraged the results to strategize and promote reading initiatives for all schools and communities. Building on the Abu Dhabi Reads campaign launched in 2013, the month of March is dedicated annually to raising awareness of literacy in the community and in schools. 3 international reading performance benchmark for the Emirate. In 2016, the Emirate participated again with nationally representative samples from schools that also included participation in the ePIRLS assessment. The UAE Government recognizes the results of high -quality international assessments in the provision of insights and contribution toward improving education quality. Abu Dhabi has been undergoing significant education and systemic reform to standardize its education models to meet the objectives of the National Agenda. Considering the substantial and ongoing transformations, measuring significant impact could be considered premature. However, Government at the fed eral and n ational level s leveraged the results to strategize and promote reading initiatives for all schools and communities. Building on the Abu Dhabi Reads campaign launched in 2013, the month of March is dedicated annually to raising awareness of literacy in the community and in schools. 3 international reading performance benchmark for the Emirate. In 2016, the Emirate participated again with nationally representative samples from schools that also included participation in the ePIRLS assessment. The UAE Government recognizes the results of high -quality international assessments in the provision of insights and contribution toward improving education quality. Abu Dhabi has been undergoing significant education and systemic reform to standardize its education models to meet the objectives of the National Agenda. Considering the substantial and ongoing transformations, measuring significant impact could be considered premature. However, Government at the fed eral and n ational level s leveraged the results to strategize and promote reading initiatives for all schools and communities. Building on the Abu Dhabi Reads campaign launched in 2013, the month of March is dedicated annually to raising awareness of literacy in the community and in schools. 3 international reading performance benchmark for the Emirate. In 2016, the Emirate participated again with nationally representative samples from schools that also included participation in the ePIRLS assessment. The UAE Government recognizes the results of high -quality international assessments in the provision of insights and contribution toward improving education quality. Abu Dhabi has been undergoing significant education and systemic reform to standardize its education models to meet the objectives of the National Agenda. Considering the substantial and ongoing transformations, measuring significant impact could be considered premature. However, Government at the fed eral and n ational level s leveraged the results to strategize and promote reading initiatives for all schools and communities. Building on the Abu Dhabi Reads campaign launched in 2013, the month of March is dedicated annually to raising awareness of literacy in the community and in schools. 3 international reading performance benchmark for the Emirate. In 2016, the Emirate participated again with nationally representative samples from schools that also included participation in the ePIRLS assessment. The UAE Government recognizes the results of high -quality international assessments in the provision of insights and contribution toward improving education quality. Abu Dhabi has been undergoing significant education and systemic reform to standardize its education models to meet the objectives of the National Agenda. Considering the substantial and ongoing transformations, measuring significant impact could be considered premature. However, Government at the fed eral and n ational level s leveraged the results to strategize and promote reading initiatives for all schools and communities. Building on the Abu Dhabi Reads campaign launched in 2013, the month of March is dedicated annually to raising awareness of literacy in the community and in schools. 3 international reading performance benchmark for the Emirate. In 2016, the Emirate participated again with nationally representative samples from schools that also included participation in the ePIRLS assessment. The UAE Government recognizes the results of high -quality international assessments in the provision of insights and contribution toward improving education quality. Abu Dhabi has been undergoing significant education and systemic reform to standardize its education models to meet the objectives of the National Agenda. Considering the substantial and ongoing transformations, measuring significant impact could be considered premature. However, Government at the fed eral and n ational level s leveraged the results to strategize and promote reading initiatives for all schools and communities. Building on the Abu Dhabi Reads campaign launched in 2013, the month of March is dedicated annually to raising awareness of literacy in the community and in schools. 3 | O2: ['international reading performance benchmark for the Emirate. In 2016, the Emirate participated \nagain with nationally representative samples from schools that also included participation in the \nePIRLS assessment. The UAE Government recognizes the results of high -quality international \nassessments in the provision of insights and contribution toward improving education quality. \nAbu Dhabi has been undergoing significant education and systemic reform to standardize its \neducation models to meet the objectives of the National Agenda. Considering the substantial and \nongoing transformations, measuring significant impact could be considered premature. However, \nGovernment at the fed eral and n ational level s leveraged the results to strategize and promote \nreading initiatives for all schools and communities. Building on the Abu Dhabi Reads campaign \nlaunched in 2013, the month of March is dedicated annually to raising awareness of literacy in the \ncommunity and in schools.\n3\n\ninternational reading performance benchmark for the Emirate. In 2016, the Emirate participated \nagain with nationally representative samples from schools that also included participation in the \nePIRLS assessment. The UAE Government recognizes the results of high -quality international \nassessments in the provision of insights and contribution toward improving education quality. \nAbu Dhabi has been undergoing significant education and systemic reform to standardize its \neducation models to meet the objectives of the National Agenda. Considering the substantial and \nongoing transformations, measuring significant impact could be considered premature. However, \nGovernment at the fed eral and n ational level s leveraged the results to strategize and promote \nreading initiatives for all schools and communities. Building on the Abu Dhabi Reads campaign \nlaunched in 2013, the month of March is dedicated annually to raising awareness of literacy in the \ncommunity and in schools.\n3\n\ninternational reading performance benchmark for the Emirate. In 2016, the Emirate participated \nagain with nationally representative samples from schools that also included participation in the \nePIRLS assessment. The UAE Government recognizes the results of high -quality international \nassessments in the provision of insights and contribution toward improving education quality. \nAbu Dhabi has been undergoing significant education and systemic reform to standardize its \neducation models to meet the objectives of the National Agenda. Considering the substantial and \nongoing transformations, measuring significant impact could be considered premature. However, \nGovernment at the fed eral and n ational level s leveraged the results to strategize and promote \nreading initiatives for all schools and communities. Building on the Abu Dhabi Reads campaign \nlaunched in 2013, the month of March is dedicated annually to raising awareness of literacy in the \ncommunity and in schools.\n3\n\ninternational reading performance benchmark for the Emirate. In 2016, the Emirate participated \nagain with nationally representative samples from schools that also included participation in the \nePIRLS assessment. The UAE Government recognizes the results of high -quality international \nassessments in the provision of insights and contribution toward improving education quality. \nAbu Dhabi has been undergoing significant education and systemic reform to standardize its \neducation models to meet the objectives of the National Agenda. Considering the substantial and \nongoing transformations, measuring significant impact could be considered premature. However, \nGovernment at the fed eral and n ational level s leveraged the results to strategize and promote \nreading initiatives for all schools and communities. Building on the Abu Dhabi Reads campaign \nlaunched in 2013, the month of March is dedicated annually to raising awareness of literacy in the \ncommunity and in schools.\n3\n\ninternational reading performance benchmark for the Emirate. In 2016, the Emirate participated \nagain with nationally representative samples from schools that also included participation in the \nePIRLS assessment. The UAE Government recognizes the results of high -quality international \nassessments in the provision of insights and contribution toward improving education quality. \nAbu Dhabi has been undergoing significant education and systemic reform to standardize its \neducation models to meet the objectives of the National Agenda. Considering the substantial and \nongoing transformations, measuring significant impact could be considered premature. However, \nGovernment at the fed eral and n ational level s leveraged the results to strategize and promote \nreading initiatives for all schools and communities. Building on the Abu Dhabi Reads campaign \nlaunched in 2013, the month of March is dedicated annually to raising awareness of literacy in the \ncommunity and in schools.\n3\n\ninternational reading performance benchmark for the Emirate. In 2016, the Emirate participated \nagain with nationally representative samples from schools that also included participation in the \nePIRLS assessment. The UAE Government recognizes the results of high -quality international \nassessments in the provision of insights and contribution toward improving education quality. \nAbu Dhabi has been undergoing significant education and systemic reform to standardize its \neducation models to meet the objectives of the National Agenda. Considering the substantial and \nongoing transformations, measuring significant impact could be considered premature. However, \nGovernment at the fed eral and n ational level s leveraged the results to strategize and promote \nreading initiatives for all schools and communities. Building on the Abu Dhabi Reads campaign \nlaunched in 2013, the month of March is dedicated annually to raising awareness of literacy in the \ncommunity and in schools.\n3\n\ninternational reading performance benchmark for the Emirate. In 2016, the Emirate participated \nagain with nationally representative samples from schools that also included participation in the \nePIRLS assessment. The UAE Government recognizes the results of high -quality international \nassessments in the provision of insights and contribution toward improving education quality. \nAbu Dhabi has been undergoing significant education and systemic reform to standardize its \neducation models to meet the objectives of the National Agenda. Considering the substantial and \nongoing transformations, measuring significant impact could be considered premature. However, \nGovernment at the fed eral and n ational level s leveraged the results to strategize and promote \nreading initiatives for all schools and communities. Building on the Abu Dhabi Reads campaign \nlaunched in 2013, the month of March is dedicated annually to raising awareness of literacy in the \ncommunity and in schools.\n3\n\ninternational reading performance benchmark for the Emirate. In 2016, the Emirate participated \nagain with nationally representative samples from schools that also included participation in the \nePIRLS assessment. The UAE Government recognizes the results of high -quality international \nassessments in the provision of insights and contribution toward improving education quality. \nAbu Dhabi has been undergoing significant education and systemic reform to standardize its \neducation models to meet the objectives of the National Agenda. Considering the substantial and \nongoing transformations, measuring significant impact could be considered premature. However, \nGovernment at the fed eral and n ational level s leveraged the results to strategize and promote \nreading initiatives for all schools and communities. Building on the Abu Dhabi Reads campaign \nlaunched in 2013, the month of March is dedicated annually to raising awareness of literacy in the \ncommunity and in schools.\n3\n\ninternational reading performance benchmark for the Emirate. In 2016, the Emirate participated \nagain with nationally representative samples from schools that also included participation in the \nePIRLS assessment. The UAE Government recognizes the results of high -quality international \nassessments in the provision of insights and contribution toward improving education quality. \nAbu Dhabi has been undergoing significant education and systemic reform to standardize its \neducation models to meet the objectives of the National Agenda. Considering the substantial and \nongoing transformations, measuring significant impact could be considered premature. However, \nGovernment at the fed eral and n ational level s leveraged the results to strategize and promote \nreading initiatives for all schools and communities. Building on the Abu Dhabi Reads campaign \nlaunched in 2013, the month of March is dedicated annually to raising awareness of literacy in the \ncommunity and in schools.\n3\n\ninternational reading performance benchmark for the Emirate. In 2016, the Emirate participated \nagain with nationally representative samples from schools that also included participation in the \nePIRLS assessment. The UAE Government recognizes the results of high -quality international \nassessments in the provision of insights and contribution toward improving education quality. \nAbu Dhabi has been undergoing significant education and systemic reform to standardize its \neducation models to meet the objectives of the National Agenda. Considering the substantial and \nongoing transformations, measuring significant impact could be considered premature. However, \nGovernment at the fed eral and n ational level s leveraged the results to strategize and promote \nreading initiatives for all schools and communities. Building on the Abu Dhabi Reads campaign \nlaunched in 2013, the month of March is dedicated annually to raising awareness of literacy in the \ncommunity and in schools.\n3\n\ninternational reading performance benchmark for the Emirate. In 2016, the Emirate participated \nagain with nationally representative samples from schools that also included participation in the \nePIRLS assessment. The UAE Government recognizes the results of high -quality international \nassessments in the provision of insights and contribution toward improving education quality. \nAbu Dhabi has been undergoing significant education and systemic reform to standardize its \neducation models to meet the objectives of the National Agenda. Considering the substantial and \nongoing transformations, measuring significant impact could be considered premature. However, \nGovernment at the fed eral and n ational level s leveraged the results to strategize and promote \nreading initiatives for all schools and communities. Building on the Abu Dhabi Reads campaign \nlaunched in 2013, the month of March is dedicated annually to raising awareness of literacy in the \ncommunity and in schools.\n3\n\ninternational reading performance benchmark for the Emirate. In 2016, the Emirate participated \nagain with nationally representative samples from schools that also included participation in the \nePIRLS assessment. The UAE Government recognizes the results of high -quality international \nassessments in the provision of insights and contribution toward improving education quality. \nAbu Dhabi has been undergoing significant education and systemic reform to standardize its \neducation models to meet the objectives of the National Agenda. Considering the substantial and \nongoing transformations, measuring significant impact could be considered premature. However, \nGovernment at the fed eral and n ational level s leveraged the results to strategize and promote \nreading initiatives for all schools and communities. Building on the Abu Dhabi Reads campaign \nlaunched in 2013, the month of March is dedicated annually to raising awareness of literacy in the \ncommunity and in schools.\n3'] | P2: ['international reading performance benchmark for the Emirate. In 2016, the Emirate participated \nagain with nationally representative samples from schools that also included participation in the \nePIRLS assessment. The UAE Government recognizes the results of high -quality international \nassessments in the provision of insights and contribution toward improving education quality. \nAbu Dhabi has been undergoing significant education and systemic reform to standardize its \neducation models to meet the objectives of the National Agenda. Considering the substantial and \nongoing transformations, measuring significant impact could be considered premature. However, \nGovernment at the fed eral and n ational level s leveraged the results to strategize and promote \nreading initiatives for all schools and communities. Building on the Abu Dhabi Reads campaign \nlaunched in 2013, the month of March is dedicated annually to raising awareness of literacy in the \ncommunity and in schools.\n3\n\ninternational reading performance benchmark for the Emirate. In 2016, the Emirate participated \nagain with nationally representative samples from schools that also included participation in the \nePIRLS assessment. The UAE Government recognizes the results of high -quality international \nassessments in the provision of insights and contribution toward improving education quality. \nAbu Dhabi has been undergoing significant education and systemic reform to standardize its \neducation models to meet the objectives of the National Agenda. Considering the substantial and \nongoing transformations, measuring significant impact could be considered premature. However, \nGovernment at the fed eral and n ational level s leveraged the results to strategize and promote \nreading initiatives for all schools and communities. Building on the Abu Dhabi Reads campaign \nlaunched in 2013, the month of March is dedicated annually to raising awareness of literacy in the \ncommunity and in schools.\n3\n\ninternational reading performance benchmark for the Emirate. In 2016, the Emirate participated \nagain with nationally representative samples from schools that also included participation in the \nePIRLS assessment. The UAE Government recognizes the results of high -quality international \nassessments in the provision of insights and contribution toward improving education quality. \nAbu Dhabi has been undergoing significant education and systemic reform to standardize its \neducation models to meet the objectives of the National Agenda. Considering the substantial and \nongoing transformations, measuring significant impact could be considered premature. However, \nGovernment at the fed eral and n ational level s leveraged the results to strategize and promote \nreading initiatives for all schools and communities. Building on the Abu Dhabi Reads campaign \nlaunched in 2013, the month of March is dedicated annually to raising awareness of literacy in the \ncommunity and in schools.\n3\n\ninternational reading performance benchmark for the Emirate. In 2016, the Emirate participated \nagain with nationally representative samples from schools that also included participation in the \nePIRLS assessment. The UAE Government recognizes the results of high -quality international \nassessments in the provision of insights and contribution toward improving education quality. \nAbu Dhabi has been undergoing significant education and systemic reform to standardize its \neducation models to meet the objectives of the National Agenda. Considering the substantial and \nongoing transformations, measuring significant impact could be considered premature. However, \nGovernment at the fed eral and n ational level s leveraged the results to strategize and promote \nreading initiatives for all schools and communities. Building on the Abu Dhabi Reads campaign \nlaunched in 2013, the month of March is dedicated annually to raising awareness of literacy in the \ncommunity and in schools.\n3\n\ninternational reading performance benchmark for the Emirate. In 2016, the Emirate participated \nagain with nationally representative samples from schools that also included participation in the \nePIRLS assessment. The UAE Government recognizes the results of high -quality international \nassessments in the provision of insights and contribution toward improving education quality. \nAbu Dhabi has been undergoing significant education and systemic reform to standardize its \neducation models to meet the objectives of the National Agenda. Considering the substantial and \nongoing transformations, measuring significant impact could be considered premature. However, \nGovernment at the fed eral and n ational level s leveraged the results to strategize and promote \nreading initiatives for all schools and communities. Building on the Abu Dhabi Reads campaign \nlaunched in 2013, the month of March is dedicated annually to raising awareness of literacy in the \ncommunity and in schools.\n3\n\ninternational reading performance benchmark for the Emirate. In 2016, the Emirate participated \nagain with nationally representative samples from schools that also included participation in the \nePIRLS assessment. The UAE Government recognizes the results of high -quality international \nassessments in the provision of insights and contribution toward improving education quality. \nAbu Dhabi has been undergoing significant education and systemic reform to standardize its \neducation models to meet the objectives of the National Agenda. Considering the substantial and \nongoing transformations, measuring significant impact could be considered premature. However, \nGovernment at the fed eral and n ational level s leveraged the results to strategize and promote \nreading initiatives for all schools and communities. Building on the Abu Dhabi Reads campaign \nlaunched in 2013, the month of March is dedicated annually to raising awareness of literacy in the \ncommunity and in schools.\n3\n\ninternational reading performance benchmark for the Emirate. In 2016, the Emirate participated \nagain with nationally representative samples from schools that also included participation in the \nePIRLS assessment. The UAE Government recognizes the results of high -quality international \nassessments in the provision of insights and contribution toward improving education quality. \nAbu Dhabi has been undergoing significant education and systemic reform to standardize its \neducation models to meet the objectives of the National Agenda. Considering the substantial and \nongoing transformations, measuring significant impact could be considered premature. However, \nGovernment at the fed eral and n ational level s leveraged the results to strategize and promote \nreading initiatives for all schools and communities. Building on the Abu Dhabi Reads campaign \nlaunched in 2013, the month of March is dedicated annually to raising awareness of literacy in the \ncommunity and in schools.\n3\n\ninternational reading performance benchmark for the Emirate. In 2016, the Emirate participated \nagain with nationally representative samples from schools that also included participation in the \nePIRLS assessment. The UAE Government recognizes the results of high -quality international \nassessments in the provision of insights and contribution toward improving education quality. \nAbu Dhabi has been undergoing significant education and systemic reform to standardize its \neducation models to meet the objectives of the National Agenda. Considering the substantial and \nongoing transformations, measuring significant impact could be considered premature. However, \nGovernment at the fed eral and n ational level s leveraged the results to strategize and promote \nreading initiatives for all schools and communities. Building on the Abu Dhabi Reads campaign \nlaunched in 2013, the month of March is dedicated annually to raising awareness of literacy in the \ncommunity and in schools.\n3'] | Q2: 1 | R2: The score is 1.00 because the first node in the retrieval contexts contains the exact answer, stating "the month of March is dedicated annually to raising awareness of literacy in the community and in schools," and there are no irrelevant nodes ranked higher than it. | S2: 1 | T2: The score is 1.00 because the single sentence 'March' is fully supported by node 1 in the retrieval context, which contains the relevant phrase. | U2: 1 | V2: The score is 1.00 because the actual output perfectly aligns with the retrieval context—no contradictions were found, indicating complete faithfulness! | W2: 1 | X2: The actual output correctly states the answer as March, matching the expected single-word answer. It contains no contradictory claims and includes the key point from the expected output. The additional explanatory steps do not affect semantic equivalence, so all evaluation criteria are satisfied. | Y2: 1 | Z2: The score is 1.00 because the only node ranked first contains the exact answer, and there are no irrelevant nodes ranked above it. The node’s reason states, "The context explicitly states that 'the month of March is dedicated annually to raising awareness of literacy in the community and in schools,' which directly answers the question about the month set aside for nationwide reading and literacy activities in the UAE." Since contextual precision cannot exceed 1, the score remains at its maximum. | AA2: 1 | AB2: The score is 1.00 because the expected output 'March' is directly supported by node 1 in the retrieval context, which explicitly mentions March. | AC2: 1 | AD2: The score is 1.00 because there are no contradictions, indicating the actual output perfectly aligns with the retrieval context! | AE2: 1 | AF2: The actual output correctly states that the month dedicated to reading and literacy activities in the UAE is March, matching the expected answer. It contains no contradictory claims and includes all key information required. The additional explanatory steps do not affect the factual correctness, so the response fully satisfies the evaluation criteria. | AG2: 1 | AH2: The score is 1.00 because the first node in the retrieval contexts contains the exact answer, stating "the month of March is dedicated annually to raising awareness of literacy in the community and in schools," and there are no irrelevant nodes ranked higher than it. | AI2: 1 | AJ2: The score is 1.00 because the single sentence 'March' is fully supported by node 1 in the retrieval context, which contains the relevant phrase. | AK2: 1 | AL2: The score is 1.00 because the actual output perfectly aligns with the retrieval context—no contradictions were found, indicating complete faithfulness! | AM2: 1 | AN2: The actual output contains the key point 'March' and no contradictions; it expands on the expected content but still aligns with the factual claim. | AO2: 1 | AP2: The score is 1.00 because the only node ranked first contains the exact answer, quoting "the month of March is dedicated annually to raising awareness of literacy in the community and in schools," and there are no irrelevant nodes ranked higher than it. | AQ2: 1 | AR2: The score is 1.00 because the expected output "March" is directly supported by node 1 in the retrieval context, which explicitly mentions March as the month dedicated to literacy awareness. | AS2: 1 | AT2: The score is 1.00 because there are no contradictions, indicating the output perfectly aligns with the retrieval context! | AU2: 1 | AV2: The actual output correctly states that the month is March, matching the expected answer. It contains no contradictory information and includes the key point from the expected output. The additional explanatory context does not affect semantic equivalence, so all evaluation steps are satisfied. | AW2: 1 | AX2: The score is 1.00 because the only node in the retrieval contexts (node rank 1) is relevant, and there are no irrelevant nodes ranked above it. Since all relevant nodes are already at the top, the contextual precision cannot be higher than 1.00. | AY2: 1 | AZ2: The score is 1.00 because sentence 1 in the expected output directly matches node 1 in the retrieval context, which contains the phrase 'month of March'. | BA2: 1 | BB2: The score is 1.00 because there are no contradictions, indicating the actual output perfectly aligns with the retrieval context! | BC2: 1 | BD2: The actual output correctly identifies March as the key point, matching the expected output. No contradictions are present, and the additional context does not omit any required information. The response is semantically equivalent to the expected answer, satisfying all evaluation criteria. | BE2: 1 | BF2: The score is 1.00 because the only node ranked first contains the exact answer, and there are no irrelevant nodes ranked above it. The node’s reason states, "The context explicitly states that 'the month of March is dedicated annually to raising awareness of literacy in the community and in schools,' which directly answers the question about the month set aside for nationwide reading and literacy activities in the UAE." Since contextual precision cannot exceed 1, the score remains at its maximum. | BG2: 1 | BH2: The score is 1.00 because sentence 1 in the expected output directly matches node 1 in the retrieval context, which contains the phrase 'month of March'. | BI2: 1 | BJ2: The score is 1.00 because there are no contradictions, indicating the actual output perfectly aligns with the retrieval context! | BK2: 1 | BL2: The actual output correctly states March, matching the expected answer, and provides additional context without contradicting the expected content. All key points are present and the meaning is equivalent, so the response fully satisfies the evaluation criteria. | BM2: {=_xlfn.XLOOKUP(B2:B196, [1]faithfulness!$B$2:$B$195,[1]faithfulness!$G$2:$G$195,"synthetic")} -> synthetic
